File: data/validation/knn_validation_set.csv
Fiber_Oz,Specimen_ID,Crosshead (mm),Load (N),Flex Stress (MPa),F Strain (mm/mm)
6-Oz,3,0.0019058752513956,0.0124538540840149,0.0197680223555792,1.9058752513956306e-05
6-Oz,3,0.0106609895738075,0.421092927455902,0.6684014721522253,0.000106609895738
6-Oz,3,0.0198925736185629,0.931058406829834,1.4778704870314827,0.0001989257361856
6-Oz,3,0.0283498939097626,1.3840137720108,2.19684725716,0.0002834989390976
6-Oz,3,0.0369263325410429,1.83328580856323,2.909977473909889,0.0003692633254104
6-Oz,3,0.0453240936622024,2.26584339141846,3.5965768117753334,0.000453240936622
6-Oz,3,0.0537814157723915,2.73184370994568,4.336259857056636,0.0005378141577239
6-Oz,3,0.0622387378825806,3.17188549041748,5.03473887367854,0.0006223873788258
6-Oz,3,0.0707556173438206,3.62944531440735,5.761024308583096,0.0007075561734382
6-Oz,3,0.0792724968050607,4.08488845825195,6.483949933733253,0.0007927249680506
6-Oz,3,0.0877298225532286,4.53377485275269,7.196468020242366,0.0008772982255322
6-Oz,3,0.0961275800364092,4.98645162582397,7.915002580672968,0.000961275800364
6-Oz,3,0.104644459497649,5.44533920288086,8.64339556012835,0.0010464445949764
6-Oz,3,0.113161338958889,5.88819885253906,9.346347384982636,0.0011316133895888
6-Oz,3,0.121737779409159,6.34467935562134,10.070919612097368,0.0012173777940915
6-Oz,3,0.130195097881369,6.80034637451172,10.794200594463048,0.0013019509788136
6-Oz,3,0.138831092044711,7.26009607315063,11.523962020874016,0.0013883109204471
6-Oz,3,0.147228856803849,7.69915437698364,12.220879963466096,0.0014722885680384
6-Oz,3,0.155745743541047,8.15268039703369,12.94076253497411,0.0015574574354104
6-Oz,3,0.164441298693419,8.59288501739502,13.639500027611144,0.0016444129869341
6-Oz,3,0.172898624441586,9.03888130187988,14.347430637904573,0.0017289862444158
6-Oz,3,0.181355935637839,9.48760795593262,15.059695168147018,0.0018135593563783
6-Oz,3,0.189872822375037,9.93895053863525,15.7761119660877,0.0018987282237503
6-Oz,3,0.198330148123205,10.3907079696655,16.493187253437306,0.001983301481232
6-Oz,3,0.206847020308487,10.8492498397827,17.221031491718573,0.0020684702030848
6-Oz,3,0.215423453482799,11.2800703048706,17.904873499794604,0.0021542345348279
6-Oz,3,0.223821218241937,11.7318067550659,18.621915484231582,0.0022382121824193
6-Oz,3,0.232338104979135,12.1892137527466,19.347958337693026,0.0023233810497913
6-Oz,3,0.240795430727303,12.6252431869507,20.0400685507154,0.002407954307273
6-Oz,3,0.249252741923556,13.0490865707397,20.712835826570952,0.0024925274192355
6-Oz,3,0.257769628660753,13.4929733276367,21.417417980375717,0.0025776962866075
6-Oz,3,0.266167393419892,13.9277181625366,22.10748914688349,0.0026616739341989
6-Oz,3,0.274684280157089,14.3696527481079,22.808972616044286,0.0027468428015708
6-Oz,3,0.283201137790456,14.8134708404541,23.51344577849857,0.0028320113779045
6-Oz,3,0.291598902549595,15.256688117981,24.21696526663651,0.0029159890254959
6-Oz,3,0.300115789286792,15.6997718811035,24.920272827148413,0.0030011578928679
6-Oz,3,0.30863267602399,16.1425342559814,25.62307024758952,0.0030863267602399
6-Oz,3,0.317209109198302,16.5972805023193,26.34488968622112,0.003172091091983
6-Oz,3,0.325785542372614,17.0284023284912,27.02921004522413,0.0032578554237261
6-Oz,3,0.334302429109812,17.4737930297852,27.736179412357465,0.0033430242910981
6-Oz,3,0.342759740306064,17.9050369262695,28.42069353376111,0.0034275974030606
6-Oz,3,0.351217080606148,18.3341083526611,29.101759289938254,0.0035121708060614
6-Oz,3,0.359912635758519,18.7990474700928,29.839757889036186,0.0035991263575851
6-Oz,3,0.368489068932831,19.2488040924072,30.553657289535245,0.0036848906893283
6-Oz,3,0.37688683369197,19.674165725708,31.2288344852508,0.0037688683369197
6-Oz,3,0.385344144888222,20.1269683837891,31.947568863157304,0.0038534414488822
6-Oz,3,0.393801456084475,20.5566062927246,32.629533797975554,0.0039380145608447
6-Oz,3,0.402318342821673,21.0017738342285,33.33614894321985,0.0040231834282167
6-Oz,3,0.410894775995985,21.4534225463867,34.05305166093127,0.0041089477599598
6-Oz,3,0.419292540755123,21.8793926239014,34.72919464111334,0.0041929254075512
6-Oz,3,0.427809427492321,22.3182697296143,35.42582496764175,0.0042780942749232
6-Oz,3,0.436266738688573,22.7610511779785,36.12865266345794,0.0043626673868857
6-Oz,3,0.444664503447711,23.1911163330078,36.811295766679045,0.0044466450344771
6-Oz,3,0.453181390184909,23.6226196289063,37.4962216331846,0.004531813901849
6-Oz,3,0.461698276922107,24.0732975006104,38.21158333430222,0.004616982769221
6-Oz,3,0.470155588118359,24.5072803497314,38.90044499957365,0.0047015558811835
6-Oz,3,0.478732021292672,24.9469127655029,39.59827423095699,0.0047873202129267
6-Oz,3,0.48712978605181,25.3947257995605,40.30908857073096,0.0048712978605181
6-Oz,3,0.495587126351893,25.8278026580811,40.996512155684286,0.0049558712635189
6-Oz,3,0.50422310596332,26.2629222869873,41.687178233313176,0.0050422310596332
6-Oz,3,0.512680446263403,26.7077922821045,42.39332108270556,0.005126804462634
6-Oz,3,0.521256879437715,27.1453094482422,43.087792774987626,0.0052125687943771
6-Oz,3,0.529833312612027,27.5831718444824,43.78281245155937,0.0052983331261202
6-Oz,3,0.53829065291211,28.0163288116455,44.4703631930881,0.005382906529121
6-Oz,3,0.546807539649308,28.4641990661621,45.18126835898746,0.005468075396493
6-Oz,3,0.55538397282362,28.8997211456299,45.8725732470316,0.0055538397282362
6-Oz,3,0.563960405997932,29.3498687744141,46.5870932927208,0.0056396040599793
6-Oz,3,0.572417688090354,29.7921943664551,47.28919740707159,0.0057241768809035
6-Oz,3,0.580875028390437,30.2238121032715,47.97430492582778,0.0058087502839043
6-Oz,3,0.589332368690521,30.6654357910156,48.67529490637397,0.0058933236869052
6-Oz,3,0.597730104345828,31.0840911865234,49.33982728019587,0.0059773010434582
6-Oz,3,0.606366142164916,31.5464363098145,50.07370842827699,0.0060636614216491
6-Oz,3,0.614882970694453,31.9695701599121,50.74534946017794,0.0061488297069445
6-Oz,3,0.623280764557421,32.3962669372559,51.42264593215223,0.0062328076455742
6-Oz,3,0.631738104857504,32.8342437744141,52.11784726097477,0.006317381048575
6-Oz,3,0.640135840512812,33.266902923584,52.80460781521271,0.0064013584051281
6-Oz,3,0.648712273687124,33.6501998901367,53.413015698629685,0.0064871227368712
6-Oz,3,0.657288706861436,34.1120872497559,54.14617023770778,0.0065728870686143
6-Oz,3,0.66562689607963,34.5518379211426,54.84418717641682,0.0066562689607962
6-Oz,3,0.674203387461603,34.9922561645508,55.543263753255246,0.006742033874616
6-Oz,3,0.68260112311691,35.4276504516602,56.23436579628603,0.0068260112311691
6-Oz,3,0.691177556291223,35.8875961303711,56.96443830217636,0.0069117755629122
6-Oz,3,0.699753989465535,36.3155097961426,57.643666343083495,0.0069975398946553
6-Oz,3,0.708270876202732,36.749324798584,58.33226158505397,0.0070827087620273
6-Oz,3,0.71678776293993,37.189769744873,59.03138054741747,0.0071678776293993
6-Oz,3,0.725364196114242,37.5761985778809,59.64475964743001,0.0072536419611424
6-Oz,3,0.733821536414325,38.0185089111328,60.34683954148064,0.0073382153641432
6-Oz,3,0.742338423151523,38.4689788818359,61.06187124100936,0.0074233842315152
6-Oz,3,0.750974402762949,38.9209518432617,61.77928864009794,0.0075097440276294
6-Oz,3,0.759372138418257,39.3615417480469,62.47863769531255,0.0075937213841825
6-Oz,3,0.76794862980023,39.8164138793945,63.200656951419845,0.0076794862980023
6-Oz,3,0.776346365455538,40.254825592041,63.896548558795246,0.0077634636545553
6-Oz,3,0.784803705755621,40.7045669555664,64.61042373899429,0.0078480370575562
6-Oz,3,0.793260987848043,41.1396751403809,65.30107165139826,0.0079326098784804
6-Oz,3,0.801837421022356,41.5047836303711,65.880608937097,0.0080183742102235
6-Oz,3,0.810354307759553,41.9628944396973,66.6077689519005,0.0081035430775955
6-Oz,3,0.818811648059636,42.4101409912109,67.31768411303318,0.0081881164805963
6-Oz,3,0.827209383714944,42.8528022766113,68.0203210739862,0.0082720938371494
6-Oz,3,0.835607177577913,43.3068313598633,68.74100215851318,0.0083560717757791
6-Oz,3,0.844183610752225,43.7611961364746,69.46221608964223,0.0084418361075222
6-Oz,3,0.852760043926537,44.2181434631348,70.18752930656319,0.0085276004392653
6-Oz,3,0.86121738422662,44.6740570068359,70.91120159815222,0.0086121738422661
6-Oz,3,0.869734270963818,45.0271415710449,71.47165328737286,0.0086973427096381
6-Oz,3,0.878132006619126,45.4805374145508,72.19132922944573,0.0087813200661912
6-Oz,3,0.886648893356323,45.9431228637695,72.92559184725319,0.0088664889335632
6-Oz,3,0.895344419404864,46.4065628051758,73.66121080186636,0.0089534441940486
6-Oz,3,0.903861306142062,46.8558540344238,74.37437148321239,0.0090386130614206
6-Oz,3,0.912318646442145,47.316333770752,75.10529169960635,0.0091231864644214
6-Oz,3,0.920835533179343,47.7734870910645,75.83093189057858,0.0092083553317934
6-Oz,3,0.92935241991654,48.1300086975098,76.39683920239652,0.0092935241991654
6-Oz,3,0.937869306653738,48.6085624694824,77.15644836425778,0.0093786930665373
6-Oz,3,0.946505286265165,49.0735778808594,77.8945680648562,0.0094650528626516
6-Oz,3,0.954903021920472,49.5227966308594,78.60761369977683,0.0095490302192047
6-Oz,3,0.963360362220556,49.9661598205566,79.3113647945343,0.0096336036222055
6-Oz,3,0.971877248957753,50.4135551452637,80.02151610359319,0.0097187724895775
6-Oz,3,0.980274984613061,50.852855682373,80.7188185434492,0.0098027498461306
6-Oz,3,0.988732324913144,51.2111740112305,81.28757779560398,0.0098873232491314
6-Oz,3,0.997308758087456,51.6672172546387,82.01145595974398,0.0099730875808745
6-Oz,3,1.00570649374276,52.1161193847656,82.72399902343746,0.0100570649374276
6-Oz,3,1.01428292691708,52.5732345581055,83.44957866365952,0.0101428292691708
6-Oz,3,1.02268077898771,53.0279006958008,84.17127094571556,0.010226807789877
6-Oz,3,1.03119760751724,53.4859848022461,84.89838857499382,0.0103119760751724
6-Oz,3,1.03965494781733,53.9272079467773,85.59874277266239,0.0103965494781733
6-Oz,3,1.04823138099164,54.3192901611328,86.22109549386158,0.0104823138099164
6-Oz,3,1.05674820952117,54.7721366882324,86.9398995051308,0.0105674820952117
6-Oz,3,1.06520554982126,55.2429122924805,87.68716236901668,0.0106520554982126
6-Oz,3,1.07366289012134,55.6936149597168,88.40256342812191,0.0107366289012134
6-Oz,3,1.08212023042142,56.1439666748047,89.11740742032494,0.0108212023042142
6-Oz,3,1.09081575646996,56.6003227233887,89.841782100617,0.0109081575646996
6-Oz,3,1.09939218964428,56.9754180908203,90.43717157273063,0.0109939218964428
6-Oz,3,1.10784952994436,57.4393310546875,91.17354135664684,0.0110784952994435
6-Oz,3,1.11642596311867,57.913745880127,91.92658076210635,0.0111642596311867
6-Oz,3,1.12482369877398,58.3647613525391,92.64247833736366,0.0112482369877397
6-Oz,3,1.13334064371884,58.8278274536133,93.3775038946243,0.0113334064371884
6-Oz,3,1.1419765651226,59.2935066223145,94.116677178277,0.011419765651226
6-Oz,3,1.15037441719323,59.6594543457031,94.69754658048112,0.0115037441719323
6-Oz,3,1.158831641078,60.1261291503906,95.43830023871524,0.01158831641078
6-Oz,3,1.16734858602285,60.5767631530762,96.15359230647016,0.0116734858602284
6-Oz,3,1.17574632167816,61.0446319580078,96.89624120318696,0.0117574632167816
6-Oz,3,1.18426326662302,61.4840507507324,97.5937313503689,0.0118426326662301
6-Oz,3,1.19278009515256,61.9512100219727,98.33525400313128,0.0119278009515256
6-Oz,3,1.20117783080786,62.3941268920898,99.0382966541108,0.0120117783080786
6-Oz,3,1.20975426398218,62.7669906616211,99.6301439073351,0.0120975426398217
6-Oz,3,1.21815211605281,63.2478446960449,100.39340427943635,0.012181521160528
6-Oz,3,1.22660933993757,63.710262298584,101.12740047394288,0.0122660933993757
6-Oz,3,1.23518577311188,64.1711959838867,101.8590412442646,0.0123518577311188
6-Oz,3,1.24370271805674,64.6293106079102,102.58620731414318,0.0124370271805674
6-Oz,3,1.25221954658628,65.0880889892578,103.31442696707587,0.0125221954658628
6-Oz,3,1.26073649153113,65.5459671020508,104.04121762230288,0.0126073649153113
6-Oz,3,1.26919383183122,63.4576377868652,100.72640918550032,0.0126919383183122
6-Oz,3,1.27771066036075,64.2136917114258,101.92649478004095,0.0127771066036075
6-Oz,3,1.28634669817984,64.8387069702148,102.91858249240444,0.0128634669817983
6-Oz,3,1.29486352670938,65.3704147338867,103.76256306966144,0.0129486352670938
6-Oz,3,1.30343995988369,65.8611907958984,104.54157269190225,0.0130343995988369
6-Oz,3,1.31189730018377,66.3504867553711,105.31823294503349,0.0131189730018377
6-Oz,3,1.32035464048386,66.8546295166016,106.11845955016128,0.0132035464048386
6-Oz,3,1.32881198078394,67.3373107910156,106.88462030319936,0.0132881198078393
6-Oz,3,1.33744790218771,67.8368453979492,107.67753237769716,0.013374479021877
6-Oz,3,1.34596484713256,68.316520690918,108.43892173161588,0.0134596484713256
6-Oz,3,1.35436258278787,68.7945022583008,109.1976226322235,0.0135436258278787
6-Oz,3,1.36276031844318,69.2651748657227,109.94472200908363,0.0136276031844318
6-Oz,3,1.37121765874326,69.7482986450195,110.71158515082462,0.0137121765874325
6-Oz,3,1.37967499904335,70.2361526489258,111.48595658559653,0.0137967499904334
6-Oz,3,1.38825143221766,70.7160568237305,112.24770924401668,0.0138825143221766
6-Oz,3,1.39670877251774,71.192138671875,113.00339471726193,0.0139670877251774
6-Oz,3,1.40522560104728,71.679817199707,113.77748761858255,0.0140522560104727
6-Oz,3,1.41368294134736,72.1478958129883,114.52046954442588,0.0141368294134736
6-Oz,3,1.42214028164744,72.6267318725586,115.28052678183904,0.0142214028164743
6-Oz,3,1.43071671482176,73.1067962646484,116.04253375341015,0.0143071671482176
6-Oz,3,1.43923354335129,73.4965209960938,116.66114443824416,0.0143923354335128
6-Oz,3,1.44769088365138,73.9858779907227,117.43790157257573,0.0144769088365138
6-Oz,3,1.45626731682569,74.4647064208984,118.19794669983874,0.0145626731682569
6-Oz,3,1.46472465712577,74.9309692382813,118.93804640997034,0.0146472465712576
6-Oz,3,1.47324160207063,75.4022598266602,119.68612670898445,0.0147324160207063
6-Oz,3,1.48193712811917,74.5266571044922,118.2962811182416,0.0148193712811917
6-Oz,3,1.49033486377448,75.1207427978516,119.23927428230414,0.0149033486377448
6-Oz,3,1.49891129694879,75.6334228515625,120.0530521453373,0.0149891129694879
6-Oz,3,1.50742824189365,76.1141738891602,120.81614903041302,0.0150742824189365
6-Oz,3,1.51588546577841,76.6039810180664,121.59362066359748,0.0151588546577841
6-Oz,3,1.52434280607849,77.1029815673828,122.38568502759176,0.0152434280607849
6-Oz,3,1.53285975102335,77.5872192382813,123.1543162512402,0.0153285975102334
6-Oz,3,1.54137657955289,78.0677719116211,123.91709827241444,0.0154137657955289
6-Oz,3,1.54989352449775,78.5405654907227,124.66756427098842,0.0154989352449775
6-Oz,3,1.55823165550828,78.9312286376953,125.28766450427824,0.0155823165550828
6-Oz,3,1.56668899580836,79.4030838012695,126.03664095439603,0.0156668899580836
6-Oz,3,1.57514633610845,79.8833923339844,126.79903545076893,0.0157514633610845
6-Oz,3,1.58372276928276,80.3663711547852,127.56566849965904,0.0158372276928276
6-Oz,3,1.59223959781229,80.8410949707031,128.3191983661954,0.0159223959781229
6-Oz,3,1.60075654275715,81.324089050293,129.0858556353857,0.0160075654275715
6-Oz,3,1.60915427841246,81.7794418334961,129.8086378309462,0.0160915427841246
6-Oz,3,1.61761161871254,80.9142227172852,128.43527415442097,0.0161761161871254
6-Oz,3,1.62624765653163,81.5865249633789,129.50242057679193,0.0162624765653163
6-Oz,3,1.63482408970594,82.0760116577148,130.2793835836743,0.0163482408970594
6-Oz,3,1.64328131359071,82.5532684326172,131.03693402002733,0.0164328131359071
6-Oz,3,1.65179825853556,83.0488815307617,131.82362147739954,0.0165179825853555
6-Oz,3,1.66025559883565,83.5341415405273,132.59387546115445,0.0166025559883565
6-Oz,3,1.66877242736518,84.0052719116211,133.3417014470176,0.0166877242736518
6-Oz,3,1.67746795341372,84.496940612793,134.1221279568143,0.0167746795341372
6-Oz,3,1.68592529371381,84.9766387939453,134.88355364118303,0.0168592529371381
6-Oz,3,1.69444223865867,85.4416275024414,135.6216309562562,0.0169444223865866
6-Oz,3,1.70289946254343,85.9121475219727,136.3684881301154,0.0170289946254343
6-Oz,3,1.71135680284351,86.3201904296875,137.01617528521825,0.0171135680284351
6-Oz,3,1.71987374778837,86.7894668579102,137.76105850461937,0.0171987374778837
6-Oz,3,1.72839057631791,87.2461013793945,138.48587520538808,0.0172839057631791
6-Oz,3,1.73684791661799,86.7365417480469,137.67705039372527,0.0173684791661799
6-Oz,3,1.74536474514753,87.2144165039063,138.43558175223225,0.0174536474514753
6-Oz,3,1.75376259721816,87.7033996582031,139.21174548921127,0.0175376259721816
6-Oz,3,1.76216033287346,88.1745681762695,139.9596320258246,0.0176216033287346
6-Oz,3,1.77061767317355,88.6395874023438,140.69775778149813,0.0177061767317355
6-Oz,3,1.77919410634786,89.1115036010742,141.4468311128162,0.0177919410634786
6-Oz,3,1.78777053952217,89.6001358032227,142.22243778289317,0.0178777053952217
6-Oz,3,1.79622787982225,90.0629043579102,142.9569910443019,0.0179622787982225
6-Oz,3,1.80468522012234,90.5377731323242,143.7107510036892,0.0180468522012234
6-Oz,3,1.8131424440071,90.9953994750977,144.4371420239646,0.0181314244400709
6-Oz,3,1.82171887718141,91.4660797119141,145.18425351097477,0.0182171887718141
6-Oz,3,1.8303549150005,91.9289703369141,145.9190005347843,0.018303549150005
6-Oz,3,1.83881225530058,92.3067169189453,146.51859828404017,0.0183881225530057
6-Oz,3,1.84732908383012,92.7695999145508,147.2533331976997,0.0184732908383012
6-Oz,3,1.85572693590075,93.2230606079102,147.97311207604795,0.0185572693590075
6-Oz,3,1.86424376443028,92.7828674316406,147.27439274863585,0.0186424376443028
6-Oz,3,1.87293929047883,93.2962036132813,148.08921208457352,0.0187293929047883
6-Oz,3,1.88139663077891,93.7690887451172,148.83982340494796,0.018813966307789
6-Oz,3,1.88991357572377,94.2400512695313,149.58738296751002,0.0188991357572377
6-Oz,3,1.89837079960853,94.6950454711914,150.3095959860181,0.0189837079960852
6-Oz,3,1.90682813990861,95.1608200073242,151.04892064654635,0.0190682813990861
6-Oz,3,1.91534508485347,95.6125030517578,151.76587785993303,0.0191534508485347
6-Oz,3,1.92386191338301,96.0656509399414,152.48516022212922,0.0192386191338301
6-Oz,3,1.93225964903831,96.5163497924805,153.20055522615954,0.0193225964903831
6-Oz,3,1.94077659398317,96.9403915405273,153.87363736591635,0.0194077659398317
6-Oz,3,1.94917432963848,97.3566818237305,154.53441559322303,0.0194917432963848
6-Oz,3,1.95769127458334,97.8058700561523,155.24741278754334,0.0195769127458334
6-Oz,3,1.96620798669755,98.2667388916016,155.97895062158986,0.0196620798669754
6-Oz,3,1.97466532699764,98.7111282348633,156.68433053152907,0.0197466532699764
6-Oz,3,1.98324187658727,99.1554260253906,157.3895651196676,0.0198324187658727
6-Oz,3,1.99175882153213,98.7633895874023,156.76728505936876,0.0199175882153213
6-Oz,3,2.00015655718744,99.2196044921875,157.49143570188494,0.0200015655718743
6-Oz,3,2.00867326930165,99.6910781860352,158.23980664450033,0.0200867326930164
6-Oz,3,2.01724981889129,100.159126281738,158.9827401297429,0.0201724981889129
6-Oz,3,2.02582636848092,100.608695983887,159.69634283156668,0.0202582636848092
6-Oz,3,2.03434308059514,101.071449279785,160.4308718726746,0.0203434308059514
6-Oz,3,2.04280042089522,101.529525756836,161.15797739180317,0.0204280042089522
6-Oz,3,2.05131736584008,101.97477722168,161.86472574869842,0.0205131736584008
6-Oz,3,2.05971510149539,102.428649902344,162.58515857514925,0.0205971510149539
6-Oz,3,2.0684702321887,102.903755187988,163.33929394918732,0.020684702321887
6-Oz,3,2.07698717713356,103.338172912598,164.02884589301271,0.0207698717713356
6-Oz,3,2.08538491278887,103.773422241211,164.7197178431921,0.0208538491278887
6-Oz,3,2.09390162490308,104.147033691406,165.31275189112063,0.0209390162490308
6-Oz,3,2.10223998874426,104.583145141602,166.00499228825717,0.0210223998874426
6-Oz,3,2.11075693368912,105.022613525391,166.7025611514143,0.0211075693368912
6-Oz,3,2.11939285509288,105.457809448242,167.3933483305429,0.0211939285509288
6-Oz,3,2.12773098610342,105.873275756836,168.0528186616445,0.0212773098610342
6-Oz,3,2.1361883264035,105.261207580566,167.08128187391426,0.0213618832640349
6-Oz,3,2.14464566670358,105.706596374512,167.78824821351114,0.0214464566670358
6-Oz,3,2.15316261164844,106.164505004883,168.5150873093381,0.0215316261164843
6-Oz,3,2.16173892840743,106.619468688965,169.23725188724606,0.0216173892840743
6-Oz,3,2.17019626870751,107.069595336914,169.95173863002225,0.0217019626870751
6-Oz,3,2.17871321365237,107.526336669922,170.6767248728921,0.0217871321365237
6-Oz,3,2.18728953041136,107.97777557373,171.3932945614762,0.0218728953041136
6-Oz,3,2.19568749889731,108.432800292969,172.11555602058576,0.0219568749889731
6-Oz,3,2.20420421101153,108.865829467773,172.8029039171,0.0220420421101152
6-Oz,3,2.21284036524594,109.316635131836,173.51846846323176,0.0221284036524594
6-Oz,3,2.22129747271538,109.702529907227,174.1309998527413,0.0222129747271538
6-Oz,3,2.22987402230501,110.143775939941,174.83139038085872,0.0222987402230501
6-Oz,3,2.23833136260509,110.575637817383,175.51688542441747,0.0223833136260509
6-Oz,3,2.24684830754995,111.018760681152,176.22025504944764,0.0224684830754995
6-Oz,3,2.25530564785004,111.449562072754,176.90406678214924,0.0225530564785004
6-Oz,3,2.26388196460903,110.641098022461,175.62079051184287,0.0226388196460903
6-Oz,3,2.27245851419866,111.278366088867,176.63232712518572,0.0227245851419866
6-Oz,3,2.28091585449874,111.715476989746,177.32615395197777,0.0228091585449874
6-Oz,3,2.28937296196818,112.162223815918,178.03527589828258,0.0228937296196818
6-Oz,3,2.29783030226827,112.608596801758,178.74380444723494,0.0229783030226826
6-Oz,3,2.30616866610944,113.033508300781,179.41826714409683,0.0230616866610944
6-Oz,3,2.31486419215798,113.468376159668,180.10853358677463,0.0231486419215798
6-Oz,3,2.32326192781329,113.899688720703,180.79315669952857,0.0232326192781329
6-Oz,3,2.33171926811337,114.329490661621,181.475382002573,0.0233171926811337
6-Oz,3,2.34017660841346,114.751655578613,182.14548504541747,0.0234017660841346
6-Oz,3,2.34857434406877,115.192687988281,182.8455364893349,0.0234857434406877
6-Oz,3,2.35721026547253,115.61548614502,183.51664467463493,0.0235721026547253
6-Oz,3,2.36572721041739,116.051651000977,184.20896984282064,0.0236572721041739
6-Oz,3,2.37424415536225,115.507545471191,183.34531027173173,0.0237424415536225
6-Oz,3,2.38276086747646,116.073654174805,184.24389551556348,0.0238276086747646
6-Oz,3,2.39115860313177,116.501045227051,184.9222940111921,0.0239115860313177
6-Oz,3,2.39973515272141,116.954711914063,185.6423998635921,0.0239973515272141
6-Oz,3,2.40843067876995,117.395751953125,186.34246341765876,0.0240843067876995
6-Oz,3,2.41688801907003,117.830528259277,187.03258453853493,0.0241688801907003
6-Oz,3,2.42534535937011,118.265121459961,187.72241501581112,0.0242534535937011
6-Oz,3,2.43386230431497,118.69263458252,188.4010072738413,0.0243386230431497
6-Oz,3,2.44231964461505,119.055221557617,188.97654215494765,0.0244231964461505
6-Oz,3,2.45083635672927,119.487159729004,189.6621583000064,0.0245083635672926
6-Oz,3,2.4594129063189,119.910858154297,190.3346954830112,0.024594129063189
6-Oz,3,2.46787024661899,120.316993713379,190.9793551006016,0.0246787024661899
6-Oz,3,2.47644656337798,120.144569396973,190.70566570948097,0.0247644656337798
6-Oz,3,2.48484429903328,120.262588500977,190.89299762059844,0.0248484429903328
6-Oz,3,2.49324226751924,120.671417236328,191.54193212115555,0.0249324226751924
6-Oz,3,2.50169937498868,121.107299804688,192.2338092137905,0.0250169937498868
6-Oz,3,2.51021631993353,121.535316467285,192.91320074172225,0.0251021631993353
6-Oz,3,2.51879286952317,121.969566345215,193.6024862622461,0.0251879286952317
6-Oz,3,2.52725020982325,122.389709472656,194.26938011532695,0.0252725020982325
6-Oz,3,2.53564794547856,122.81982421875,194.95210193452385,0.0253564794547855
6-Oz,3,2.54410528577864,123.23779296875,195.6155443948413,0.0254410528577864
6-Oz,3,2.55268160253763,123.670448303223,196.3022988940048,0.0255268160253763
6-Oz,3,2.56125815212727,124.097511291504,196.980176653181,0.0256125815212726
6-Oz,3,2.56971549242735,124.45329284668,197.54490928044444,0.0256971549242734
6-Oz,3,2.57829180918634,124.880569458008,198.22312612382223,0.0257829180918634
6-Oz,3,2.58668954484165,125.282691955566,198.8614158024857,0.0258668954484165
6-Oz,3,2.59520648978651,125.679298400879,199.49094984266512,0.0259520648978651
6-Oz,3,2.60396162047982,125.01180267334,198.43143281482543,0.0260396162047981
6-Oz,3,2.61241896077991,125.404327392578,199.05448792472697,0.0261241896077991
6-Oz,3,2.62093590572476,125.850326538086,199.762423076327,0.0262093590572476
6-Oz,3,2.6293930131942,126.274307250977,200.43540833488416,0.026293930131942
6-Oz,3,2.63785035349429,126.705619812012,201.12003144763813,0.0263785035349429
6-Oz,3,2.64636729843915,127.13005065918,201.7937312050476,0.0264636729843915
6-Oz,3,2.65494384802878,127.522407531738,202.4165198916476,0.0265494384802877
6-Oz,3,2.66334158368409,127.944969177246,203.08725266229524,0.0266334158368409
6-Oz,3,2.6718582957983,128.353393554688,203.7355453249016,0.026718582957983
6-Oz,3,2.68031563609838,128.764678955078,204.38837929377465,0.0268031563609838
6-Oz,3,2.68871337175369,129.172409057617,205.03556993272545,0.0268871337175369
6-Oz,3,2.69723031669855,129.516021728516,205.58098687066035,0.0269723031669855
6-Oz,3,2.70568765699863,129.927154541016,206.23357863653337,0.0270568765699862
6-Oz,3,2.71420460194349,130.345245361328,206.8972148592508,0.0271420460194348
6-Oz,3,2.72272154688835,130.759414672852,207.55462646484443,0.0272272154688835
6-Oz,3,2.73111928254366,129.936798095703,206.24888586619525,0.0273111928254366
6-Oz,3,2.73963599465787,130.581069946289,207.27153959728412,0.0273963599465787
6-Oz,3,2.74815293960273,131.000076293945,207.936629038008,0.0274815293960273
6-Oz,3,2.75672948919237,131.414321899414,208.5941617451016,0.0275672948919237
6-Oz,3,2.76530580595136,131.842987060547,209.2745826357889,0.0276530580595136
6-Oz,3,2.77376314625144,132.250595092773,209.92157951233813,0.0277376314625144
6-Oz,3,2.78222048655152,132.676483154297,210.59759230840797,0.0278222048655152
6-Oz,3,2.79073743149638,133.087951660156,211.25071692088247,0.0279073743149638
6-Oz,3,2.79943295754492,133.50910949707,211.91922142392067,0.0279943295754492
6-Oz,3,2.80794990248978,133.921966552734,212.5745500837048,0.0280794990248978
6-Oz,3,2.81640700995922,134.327575683594,213.2183741009429,0.0281640700995922
6-Oz,3,2.82492395490408,134.654495239258,213.73729403056825,0.0282492395490408
6-Oz,3,2.83332169055939,135.045349121094,214.35769701760955,0.0283332169055938
6-Oz,3,2.84183863550425,135.452407836914,215.0038219633556,0.0284183863550425
6-Oz,3,2.85047455690801,135.838500976563,215.6166682167667,0.0285047455690801
6-Oz,3,2.85887229256332,136.231658935547,216.24072846912225,0.0285887229256332
6-Oz,3,2.8673296328634,136.556442260742,216.75625755673332,0.028673296328634
6-Oz,3,2.87572760134935,135.722122192383,215.43193998790957,0.0287572760134935
6-Oz,3,2.88418470881879,136.099624633789,216.0311502123635,0.0288418470881879
6-Oz,3,2.89270165376365,136.527069091797,216.70963347904288,0.0289270165376365
6-Oz,3,2.90121859870851,136.925689697266,217.34236459883496,0.029012185987085
6-Oz,3,2.90967593900859,137.342193603516,218.00348191034288,0.0290967593900859
6-Oz,3,2.91825225576758,137.74055480957,218.6358012850318,0.0291825225576758
6-Oz,3,2.92664999142289,138.141525268555,219.27226233103968,0.0292664999142289
6-Oz,3,2.93516693636775,138.525726318359,219.8821052672365,0.0293516693636775
6-Oz,3,2.94374348595738,138.953552246094,220.56119404141907,0.0294374348595738
6-Oz,3,2.9522601980716,139.339538574219,221.17387075272865,0.029522601980716
6-Oz,3,2.96077714301646,139.710189819336,221.7622060624381,0.0296077714301646
6-Oz,3,2.96935369260609,140.124969482422,222.42058648003493,0.0296935369260609
6-Oz,3,2.97781103290617,140.514755249023,223.03929404606828,0.0297781103290616
6-Oz,3,2.98632774502039,140.905578613281,223.6596485925095,0.0298632774502039
6-Oz,3,2.99490429461002,141.275894165039,224.2474510556175,0.0299490429461002
6-Oz,3,3.00342123955488,141.640411376953,224.82604980468733,0.0300342123955487
6-Oz,3,3.01199755631387,142.015090942383,225.42077927362385,0.0301199755631387
6-Oz,3,3.02039529196918,142.358352661133,225.9656391446556,0.0302039529196918
6-Oz,3,3.02879302762449,142.613861083984,226.37120806981588,0.0302879302762449
6-Oz,3,3.03725036792457,142.862686157227,226.7661685035349,0.0303725036792457
6-Oz,3,3.04588652215898,143.135314941406,227.19891260540635,0.0304588652215897
6-Oz,3,3.05434362962842,141.160217285156,224.06383696056508,0.0305434362962842
6-Oz,3,3.0628009699285,141.417007446289,224.47144039093493,0.030628009699285
6-Oz,3,3.07119870558381,141.84245300293,225.1467507983016,0.030711987055838
6-Oz,3,3.07965604588389,142.259796142578,225.80920022631432,0.0307965604588389
6-Oz,3,3.08823259547353,142.695495605469,226.50078667534763,0.0308823259547353
6-Oz,3,3.09674954041839,143.110916137695,227.1601843455477,0.0309674954041839
6-Oz,3,3.10520688071847,143.537567138672,227.83740815662225,0.0310520688071847
6-Oz,3,3.11366398818791,143.94841003418,228.4895397367937,0.0311366398818791
6-Oz,3,3.12212132848799,144.353912353516,229.1331942119302,0.0312212132848799
6-Oz,3,3.13069787807763,144.784210205078,229.816206674727,0.0313069787807763
6-Oz,3,3.13927419483662,145.194778442383,230.46790228949683,0.0313927419483662
6-Oz,3,3.14779113978148,145.598129272461,231.10814170231907,0.0314779113978148
6-Oz,3,3.15624848008156,146.009826660156,231.76162961929523,0.0315624848008155
6-Oz,3,3.16488440148532,146.410659790039,232.3978726826016,0.0316488440148532
6-Oz,3,3.17334174178541,146.813827514648,233.03782145182225,0.0317334174178541
6-Oz,3,3.18179908208549,147.203796386719,233.6568196614588,0.0318179908208548
6-Oz,3,3.19049460813403,147.596893310547,234.2807830326143,0.0319049460813403
6-Oz,3,3.19889234378934,147.9775390625,234.8849826388889,0.0319889234378934
6-Oz,3,3.20746889337897,148.342498779297,235.46428377666192,0.0320746889337896
6-Oz,3,3.21586662903428,148.704971313477,236.03963700551904,0.0321586662903427
6-Oz,3,3.22426436468959,149.081771850586,236.63773309616823,0.0322426436468959
6-Oz,3,3.23278130963445,149.433181762695,237.1955266074524,0.0323278130963445
6-Oz,3,3.24129825457931,149.778381347656,237.74346245659683,0.0324129825457931
6-Oz,3,3.24981496669352,150.102020263672,238.2571750217016,0.0324981496669352
6-Oz,3,3.2582723069936,150.428375244141,238.77519880022385,0.032582723069936
6-Oz,3,3.26672964729369,150.66423034668,239.14957197885715,0.0326672964729369
6-Oz,3,3.27518698759377,150.931747436523,239.5742022801953,0.0327518698759377
6-Oz,3,3.28364432789385,151.277877807617,240.12361556764608,0.0328364432789385
6-Oz,3,3.29222087748349,151.622817993164,240.6711396716889,0.0329222087748348
6-Oz,3,3.3007375895977,151.985870361328,241.24741327194923,0.033007375895977
6-Oz,3,3.30919492989779,152.35530090332,241.83381095765083,0.0330919492989779
6-Oz,3,3.31765227019787,152.713043212891,242.40165589347785,0.0331765227019787
6-Oz,3,3.32610961049795,150.858657836914,239.45818704272065,0.0332610961049795
6-Oz,3,3.33480513654649,151.220855712891,240.03310430617623,0.0333480513654649
6-Oz,3,3.34338168613613,151.633758544922,240.68850562686032,0.0334338168613613
6-Oz,3,3.35183902643621,152.048889160156,241.34744311135876,0.0335183902643621
6-Oz,3,3.36035573855042,152.428985595703,241.9507707868302,0.0336035573855042
6-Oz,3,3.36887268349528,152.823181152344,242.57647801959368,0.0336887268349528
6-Oz,3,3.37733002379537,153.206390380859,243.18474663628413,0.0337733002379537
6-Oz,3,3.38602554984391,153.582305908203,243.7814379495286,0.033860255498439
6-Oz,3,3.39436368085444,153.93522644043,244.3416292705238,0.0339436368085444
6-Oz,3,3.4028806257993,154.291076660156,244.9064708891365,0.034028806257993
6-Oz,3,3.41139757074416,154.656265258789,245.48613533141116,0.0341139757074416
6-Oz,3,3.41979530639946,155.005523681641,246.04051378038255,0.0341979530639946
6-Oz,3,3.42825264669955,155.374633789063,246.62640283978257,0.0342825264669955
6-Oz,3,3.43676959164441,155.729675292969,247.1899607824905,0.0343676959164441
6-Oz,3,3.44522693194449,156.068572998047,247.7278936476937,0.0344522693194449
6-Oz,3,3.45380324870348,156.447952270508,248.33008296906036,0.0345380324870348
6-Oz,3,3.46220098435879,156.795196533203,248.88126433841748,0.0346220098435878
6-Oz,3,3.47065832465887,157.146133422852,249.4383070204,0.0347065832465886
6-Oz,3,3.47917526960373,157.508255004883,250.013103182354,0.0347917526960373
6-Oz,3,3.48769221454859,157.862686157227,250.57569231305877,0.0348769221454859
6-Oz,3,3.49626853130758,158.191925048828,251.09829372829844,0.0349626853130757
6-Oz,3,3.50472587160766,158.504852294922,251.59500364273336,0.0350472587160766
6-Oz,3,3.51318321190774,158.823272705078,252.1004328652032,0.0351318321190773
6-Oz,3,3.52164055220783,159.147994995117,252.6158650716143,0.0352164055220782
6-Oz,3,3.53033607825637,159.479766845703,253.14248705667143,0.0353033607825637
6-Oz,3,3.53891239501536,159.772766113281,253.6075652591762,0.0353891239501536
6-Oz,3,3.54736973531544,160.090835571289,254.11243741474448,0.0354736973531544
6-Oz,3,3.5558866802603,160.430755615234,254.651993040054,0.035558866802603
6-Oz,3,3.56434402056038,160.766052246094,255.18420991443497,0.0356434402056037
6-Oz,3,3.57280136086047,161.086563110352,255.69295731801904,0.0357280136086047
6-Oz,3,3.58149688690901,161.427764892578,256.23454744853655,0.03581496886909
6-Oz,3,3.58989462256432,159.151336669922,252.62116931733647,0.0358989462256432
6-Oz,3,3.59841156750917,159.944213867188,253.8797045510921,0.0359841156750916
6-Oz,3,3.60680930316448,160.327850341797,254.4886513361857,0.0360680930316448
6-Oz,3,3.61526664346457,160.705703735352,255.0884186275429,0.0361526664346457
6-Oz,3,3.62378358840942,161.085556030273,255.69135877821117,0.0362378358840942
6-Oz,3,3.63224092870951,161.44255065918,256.25801691933333,0.0363224092870951
6-Oz,3,3.64069826900959,161.806259155273,256.8353319924969,0.0364069826900959
6-Oz,3,3.64921498112381,162.168869018555,257.4109032040556,0.0364921498112381
6-Oz,3,3.65767232142389,162.51692199707,257.9633682493175,0.0365767232142388
6-Oz,3,3.66612966172397,162.816253662109,258.4384978763635,0.0366612966172397
6-Oz,3,3.67470621131361,162.934494018555,258.62618098183333,0.0367470621131361
6-Oz,3,3.68316355161369,163.105026245117,258.8968670557413,0.0368316355161369
6-Oz,3,3.6916802637279,163.408325195313,259.3782939608143,0.036916802637279
6-Oz,3,3.70025681331754,163.726104736328,259.8827059306794,0.0370025681331753
6-Oz,3,3.70871415361762,164.061584472656,260.4152134486603,0.0370871415361762
6-Oz,3,3.71723086573184,164.400787353516,260.9536307198667,0.0371723086573184
6-Oz,3,3.72580741532147,164.758041381836,261.5207006060889,0.0372580741532147
6-Oz,3,3.73438373208046,165.088317871094,262.04494900173654,0.0373438373208046
6-Oz,3,3.74290067702532,165.41716003418,262.5669206891746,0.0374290067702531
6-Oz,3,3.75141762197018,165.740966796875,263.0808996775794,0.0375141762197018
6-Oz,3,3.75987496227026,166.066619873047,263.5978093222968,0.0375987496227026
6-Oz,3,3.76833230257034,166.377151489258,264.0907166496159,0.0376833230257033
6-Oz,3,3.77696822397411,166.68376159668,264.57739935980953,0.0377696822397411
6-Oz,3,3.78542556427419,167.011077880859,265.0969490172365,0.0378542556427419
6-Oz,3,3.79388290457428,167.313461303711,265.5769227043032,0.0379388290457428
6-Oz,3,3.80228064022958,167.595291137695,266.024271647135,0.0380228064022958
6-Oz,3,3.81067837588489,167.910293579102,266.52427552238413,0.0381067837588489
6-Oz,3,3.81919532082975,168.216430664063,267.01020740327465,0.0381919532082975
6-Oz,3,3.82777163758874,168.5224609375,267.4959697420635,0.0382777163758874
6-Oz,3,3.83622897788882,166.823471069336,264.79916042751745,0.0383622897788882
6-Oz,3,3.84474592283368,167.453826904297,265.79972524491586,0.0384474592283368
6-Oz,3,3.85320326313376,167.826599121094,266.39142717633973,0.0385320326313375
6-Oz,3,3.86160099878907,168.142807006836,266.8933444552953,0.0386160099878907
6-Oz,3,3.87023692019284,168.522964477539,267.4967690119667,0.0387023692019284
6-Oz,3,3.8787538651377,168.876098632813,268.0572994171635,0.038787538651377
6-Oz,3,3.887151600793,169.202651977539,268.57563805958574,0.03887151600793
6-Oz,3,3.89578775502741,169.51203918457,269.06672886439685,0.0389578775502741
6-Oz,3,3.90424486249685,169.827377319336,269.56726558624763,0.0390424486249685
6-Oz,3,3.91276180744171,170.079513549805,269.9674818250873,0.0391276180744171
6-Oz,3,3.92133835703135,170.316772460938,270.3440832713302,0.0392133835703135
6-Oz,3,3.9298553019762,170.54508972168,270.7064916217143,0.039298553019762
6-Oz,3,3.93849099054933,170.787628173828,271.0914732917905,0.0393849099054933
6-Oz,3,3.94694833084941,171.055511474609,271.5166848803317,0.0394694833084941
6-Oz,3,3.95534606650472,171.336196899414,271.9622173006572,0.0395534606650472
6-Oz,3,3.96386301144958,171.60481262207,272.38859146360323,0.0396386301144958
6-Oz,3,3.97237995639443,171.883972167969,272.83170185391907,0.0397237995639443
6-Oz,3,3.98089690133929,172.180221557617,273.30193898034446,0.0398089690133929
6-Oz,3,3.98935424163938,172.452697753906,273.73444087921587,0.0398935424163938
6-Oz,3,3.99775197729468,171.678756713867,272.50596303788416,0.0399775197729468
6-Oz,3,4.00620931759477,171.908081054688,272.8699699280763,0.0400620931759477
6-Oz,3,4.01460705325007,172.164703369141,273.27730693514445,0.0401460705325006
6-Oz,3,4.02330281212926,172.411468505859,273.6689976283476,0.0402330281212926
6-Oz,3,4.03170054778457,172.687728881836,274.1075061616445,0.0403170054778457
6-Oz,3,4.04021702706814,172.951446533203,274.5261056082588,0.0404021702706813
6-Oz,3,4.04867436736822,173.16796875,274.8697916666667,0.0404867436736822
6-Oz,3,4.05707256868482,172.189376831055,273.3164711604048,0.0405707256868482
6-Oz,3,4.06576786190271,172.488250732422,273.7908741784476,0.0406576786190271
6-Oz,3,4.07428480684757,172.713531494141,274.1484626891127,0.0407428480684757
6-Oz,3,4.08274214714766,173.00163269043,274.60576617528574,0.0408274214714766
6-Oz,3,4.09131869673729,173.28694152832,275.05863734653974,0.0409131869673729
6-Oz,3,4.0997164323926,173.588745117188,275.53769066220326,0.0409971643239259
6-Oz,3,4.10829251632094,173.881805419922,276.002865745908,0.0410829251632094
6-Oz,3,4.11692867055535,174.126358032227,276.3910444955984,0.0411692867055535
6-Oz,3,4.12538601085544,174.047668457031,276.2661404079857,0.0412538601085544
6-Oz,3,4.13396256044507,174.04817199707,276.2669396778889,0.0413396256044507
6-Oz,3,4.14247950538993,174.229629516602,276.55496748666985,0.0414247950538993
6-Oz,3,4.15087724104524,174.48371887207,276.95828392392065,0.0415087724104524
6-Oz,3,4.15933458134532,174.729415893555,277.34827919611905,0.0415933458134532
6-Oz,3,4.16785152629018,174.96923828125,277.72894965277777,0.0416785152629018
6-Oz,3,4.17630886659026,175.240005493164,278.1587388780381,0.0417630886659026
6-Oz,3,4.18482534587383,175.492630004883,278.55973016648096,0.0418482534587383
6-Oz,3,4.19322308152914,175.71907043457,278.9191594199524,0.0419322308152913
6-Oz,3,4.20168042182922,175.954605102539,279.2930239722841,0.0420168042182922
6-Oz,3,4.21013776212931,176.197662353516,279.6788291325651,0.0421013776212931
6-Oz,3,4.21871431171894,176.41748046875,280.0277467757937,0.0421871431171893
6-Oz,3,4.2272312566638,176.622467041016,280.35312228732704,0.042272312566638
6-Oz,3,4.23574820160866,176.848739624023,280.7122851174969,0.0423574820160865
6-Oz,3,4.24420554190874,177.02458190918,280.9913998558413,0.0424420554190873
6-Oz,3,4.25260327756405,177.184860229492,281.2458098880826,0.0425260327756405
6-Oz,3,4.26123943179846,177.334686279297,281.4836290147572,0.0426123943179845
6-Oz,3,4.26987512037158,177.482803344727,281.71873546782064,0.0426987512037158
6-Oz,3,4.27827285602689,175.660247802734,278.8257901630698,0.0427827285602688
6-Oz,3,4.28684940561652,176.257125854492,279.77321564205084,0.0428684940561652
6-Oz,3,4.29524714127183,176.174362182617,279.6418447343127,0.0429524714127182
6-Oz,3,4.30376408621669,176.193099975586,279.671587262835,0.0430376408621668
6-Oz,3,4.31245984509587,176.18473815918,279.658314538381,0.0431245984509587
6-Oz,3,4.32091671973467,176.032653808594,279.4169108072921,0.0432091671973467
6-Oz,3,4.32943366467953,175.848968505859,279.1253468346968,0.0432943366467952
6-Oz,3,4.33789100497961,168.955429077148,268.1832207573778,0.0433789100497961
6-Oz,3,4.34634834527969,159.303100585938,252.86206442212384,0.0434634834527969
6-Oz,3,4.35486529022455,115.76245880127,183.74993460519048,0.0435486529022455
6-Oz,3,4.36338223516941,43.9210624694824,69.7159721737816,0.043633822351694
6-Oz,3,4.37177997082472,34.0427742004395,54.036149524507145,0.0437177997082472
6-Oz,3,4.38029691576958,34.0096206665039,53.98352486746651,0.0438029691576957
6-Oz,3,4.38869465142488,33.9374847412109,53.86902339874746,0.0438869465142488
6-Oz,3,4.39715199172497,33.7053909301758,53.500620524088575,0.0439715199172496
6-Oz,3,4.40566893666983,33.5402145385742,53.2384357755146,0.0440566893666983
6-Oz,3,4.41418588161469,33.4256057739258,53.05651710146953,0.0441418588161469
6-Oz,3,4.42270236089826,33.3581466674805,52.94943915473095,0.0442270236089826
6-Oz,3,4.43127891048789,33.3128623962402,52.87755935911142,0.0443127891048789
6-Oz,3,4.4396766461432,33.2767219543457,52.82019357832652,0.0443967664614319
6-Oz,3,4.44819359108806,33.2647705078125,52.80122302827381,0.0444819359108806
6-Oz,3,4.45671053603292,33.2474708557129,52.77376326303636,0.0445671053603292
6-Oz,3,4.46528708562255,33.2365760803223,52.75646996876557,0.0446528708562255
6-Oz,3,4.47386363521218,33.2395286560059,52.761156596834766,0.0447386363521218
6-Oz,3,4.48232097551227,33.2436408996582,52.76768396771144,0.0448232097551226
6-Oz,3,4.49083745479584,33.2285041809082,52.74365743001302,0.0449083745479583
6-Oz,3,4.49923519045115,33.1771392822266,52.66212584480414,0.0449923519045115
6-Oz,3,4.50799055397511,33.1130104064941,52.56033397856207,0.0450799055397511
6-Oz,3,4.51650749891996,33.080509185791,52.5087447393508,0.0451650749891996
6-Oz,3,4.52490523457527,33.0740089416504,52.49842689150858,0.0452490523457527
6-Oz,3,4.53342217952013,33.0745048522949,52.49921405126175,0.0453342217952013
6-Oz,3,4.54176031053066,33.0954399108887,52.532444302997945,0.0454176031053066
6-Oz,3,4.5503368601203,33.1228675842285,52.5759802924262,0.045503368601203
6-Oz,3,4.55891294404864,33.1224555969238,52.57532634432349,0.0455891294404863
6-Oz,3,4.56725154072046,33.1597785949707,52.6345691983662,0.0456725154072046
6-Oz,3,4.57576802000403,33.1943778991699,52.68948872884112,0.0457576802000402
6-Oz,3,4.58416575565934,33.1770515441895,52.661986578078576,0.0458416575565934
6-Oz,3,4.59262309595942,33.1446800231934,52.6106032114181,0.0459262309595941
6-Oz,3,4.60119964554906,33.1425666809082,52.607248699854296,0.0460119964554906
6-Oz,3,4.60971659049392,33.0656929016113,52.48522682795444,0.0460971659049391
6-Oz,3,4.618173930794,32.9324531555176,52.273735167488255,0.0461817393079399
6-Oz,3,4.62675048038363,32.7761650085449,52.02565874372207,0.0462675048038363
6-Oz,3,4.63520782068372,32.6111946105957,51.76380096919953,0.0463520782068372
6-Oz,3,4.64372476562858,32.2931137084961,51.25891064840652,0.0464372476562858
6-Oz,3,4.65230084955692,32.2083168029785,51.12431238568016,0.0465230084955692
6-Oz,3,4.66075818985701,32.1101875305176,50.96855163574222,0.04660758189857
6-Oz,3,4.66939434409142,31.919116973877,50.6652650379,0.0466939434409142
6-Oz,3,4.67791128903627,30.8513717651367,48.970431373232856,0.0467791128903627
6-Oz,3,4.68630902469158,30.7695426940918,48.84054395887588,0.0468630902469158
6-Oz,3,4.69482596963644,30.6894207000732,48.71336619059239,0.0469482596963644
6-Oz,3,4.70340205356479,30.6335754394531,48.62472291976683,0.0470340205356478
6-Oz,3,4.71197860315442,30.5950508117676,48.56357271709143,0.0471197860315441
6-Oz,3,4.7204359434545,30.5586719512939,48.5058284941173,0.0472043594345449
6-Oz,3,4.72883367910981,30.4756679534912,48.3740761166527,0.0472883367910981
6-Oz,3,4.73729101940989,30.4249744415283,48.2936102246481,0.0473729101940988
6-Oz,3,4.74574835970998,30.3944206237793,48.24511210123699,0.0474574835970997
6-Oz,3,4.75432490929961,30.3601493835449,48.19071330721413,0.0475432490929961
6-Oz,3,4.7627822495997,30.2990608215332,48.09374733576698,0.047627822495997
6-Oz,3,4.77123958989978,30.2600917816162,48.03189171685111,0.0477123958989978
6-Oz,3,4.77963732555509,30.2086505889893,47.95023903014175,0.0477963732555508
6-Oz,3,4.78809466585517,30.1425075531006,47.84525008428668,0.0478809466585517
6-Oz,3,4.7966712154448,30.1069221496582,47.788765316917775,0.047966712154448
6-Oz,3,4.80524729937315,30.0478668212891,47.6950267004589,0.0480524729937315
6-Oz,3,4.81370463967323,29.9557590484619,47.548823886447465,0.0481370463967323
6-Oz,3,4.82222158461809,29.8277473449707,47.3456307063027,0.0482222158461809
6-Oz,3,4.83067892491817,29.7192764282227,47.17345464797254,0.0483067892491817
6-Oz,3,4.83919586986303,29.6281414031982,47.02879587809239,0.0483919586986303
6-Oz,3,4.84789162874222,29.4546661376953,46.753438313802064,0.0484789162874221
6-Oz,3,4.8563489690423,29.2818813323975,46.47917671809128,0.048563489690423
6-Oz,3,4.86486544832587,29.0718593597412,46.14580850752572,0.0486486544832587
6-Oz,3,4.87344199791551,28.7418003082275,45.621905251154764,0.0487344199791551
6-Oz,3,4.88183973357081,28.3423824310303,44.987908620683015,0.048818397335708
6-Oz,3,4.89035667851567,26.6381397247314,42.28276146782762,0.0489035667851567
6-Oz,3,4.89893322810531,23.4116077423096,37.16128213065016,0.0489893322810531
6-Oz,3,4.90739056840539,18.7038745880127,29.688689822242385,0.0490739056840539
6-Oz,3,4.91590751335025,18.7018299102783,29.68544430202905,0.0491590751335025
6-Oz,3,4.92436485365033,17.6563301086426,28.025920807369207,0.0492436485365033
6-Oz,3,4.92442445829511,17.6055679321289,27.945345924014127,0.0492442445829511